Workbook

Sheet 1866(ZAIN)
D6: NAME: | E6: MUHAMMAD ZAIN
D7: ROLL NO.: | E7: 1866-BS-BAF-22

Sheet DATA
A1: INCOME STATEMENT
A2: Particulars | B2: 2022 | C2: 2023 | D2: 2024
A3: Products Revenue | B3: 10930.8 | C3: 11975.4 | D3: 13314.5
A4: Services Revenue | B4: 5060.9 | C4: 5702.2 | D4: 6523.7
A5: Net Revenues | B5: 15991.7 | C5: 17677.6 | D5: 19838.2
A6: Cost of Products Sold | B6: -7935.2 | C6: -8414.2 | D6: -8927.9
A7: Cost of Services Sold | B7: -3091.7 | C7: -3406.2 | D7: -3829.8
A8: Selling and Administrative Expenses | B8: -2545.9 | C8: -2963.2 | D8: -3580.4
A9: Operating Income | B9: 2418.9 | C9: 2894 | D9: 3500.1
A10: Interest Expense | B10: -223.5 | C10: -234.5 | D10: -238.4
A11: Other Income/(Expense), net | B11: -23.3 | C11: -92.2 | D11: -19.9
A12: Earnings Before Income Taxes | B12: 2172.1 | C12: 2567.3 | D12: 3241.8
A13: Provision for Income Taxes | B13: -375.9 | C13: -498.4 | D13: -627.6
A14: Earnings from Continuing Operations | B14: 1796.2 | C14: 2068.9 | D14: 2614.2
... A18: Net Earnings Attributable to Trane Technologies plc | B18: 1756.5 | C18: 2023.9 | D18: 2567.9
A21: CASH FLOW STATEMENT
A23: Category | B23: 2022 | C23: 2023 | D23: 2024
A24: Net earnings | B24: 1774.7 | C24: 2041.7 | D24: 2589.5
A25: Discontinued operations, net of tax | B25: 21.5 | C25: 27.2 | D25: 24.7
A26: Depreciation and amortization | B26: 323.6 | C26: 348.1 | D26: 379.4
A27: Pension and other postretirement benefits | B27: 55.6 | C27: 51 | D27: 40.6
A28: Stock settled share-based compensation | B28: 56.3 | C28: 64.3 | D28: 82.9
A29: Other non-cash items, net | B29: 17.1 | C29: -32.7 | D29: -178.3
A30: Accounts and notes receivable | B30: -345.4 | C30: -110.1 | D30: -180.6
A31: Inventories | B31: -466.7 | C31: -96.4 | D31: 162.5
A32: Other current and noncurrent assets | B32: -116.8 | C32: -152.3 | D32: -162.4
A33: Accounts payable | B33: 317.9 | C33: -125.3 | D33: 100.9
A34: Other current and noncurrent liabilities | B34: 60.9 | C34: 411.3 | D34: 318.5
A35: Net cash provided by (used in) continuing operating activities | B35: 1698.7 | C35: 2426.8 | D35: 3177.7
... A64: Cash paid during the year for: Income taxes, net of refunds | B64: 321.3 | C64: 523.6 | D64: 710.5
A66: BALANCE SHEET
A67: ASSETS
A68: CURRENT ASSETS: | B68: 2022 ($ millions) | C68: 2023 ($ millions) | D68: 2024 ($ millions)
A69: Cash and cash equivalents | B69: 1220.5 | C69: 1095.3 | D69: 1590.1
A70: Accounts and notes receivable, net | B70: 2780.1 | C70: 2956.8 | D70: 3090.2
A71: Inventories | B71: 1993.8 | C71: 2152.1 | D71: 1971.5
A72: Other current assets | B72: 384.8 | C72: 665.7 | D72: 686
A73: Total current assets | B73: 6379.2 | C73: 6869.9 | D73: 7337.8
A74: Property, plant and equipment, net | B74: 1536.1 | C74: 1772.2 | D74: 2024.5
A75: Goodwill | B75: 5503.7 | C75: 6095.3 | D75: 6127.9
...

Sheet P&L
B2: INCOME STATEMENT | F2: Forecast
B3: $ in mln | C3: 2022 | D3: 2023 | E3: 2024 | F3: =E3+1 -> 2025 | G3: =F3+1 -> 2026 | H3: =G3+1 -> 2027 | I3: =H3+1 -> 2028 | J3: =I3+1 -> 2029
B4: Revenue | C4: =DATA!B5 -> 15991.7 | D4: =DATA!C5 -> 17677.6 | E4: =DATA!D5 -> 19838.2 | F4: =E4*(1+F17) -> 22096.243 | G4: =F4*(1+G17) -> 24610.795 | H4: =G4*(1+H17) -> 27411.503 | I4: =H4*(1+I17) -> 30530.933 | J4: =I4*(1+J17) -> 34005.353
B5: Cogs | C5: =(SUM(DATA!B6:B7)) -> -11026.9 | D5: =SUM(DATA!C6:C7) -> -11820.4 | E5: =SUM(DATA!D6:D7) -> -12757.7 | F5: =F4*F19 -> -14740.344 | G5: =G4*G19 -> -16417.795 | H5: =H4*H19 -> -18286.14 | I5: =I4*I19 -> -20367.103 | J5: =J4*J19 -> -22684.88
B6: Gross Profit | C6: =SUM(C4:C5) -> 4964.8 | D6: =SUM(D4:D5) -> 5857.2 | E6: =SUM(E4:E5) -> 7080.5 | F6: =SUM(F4:F5) -> 7355.8984 | G6: =SUM(G4:G5) -> 8192.9996 | H6: =SUM(H4:H5) -> 9125.363 | I6: =SUM(I4:I5) -> 10163.829 | J6: =SUM(J4:J5) -> 11320.473
B7: Operating expenses | C7: =DATA!B8-C9 -> -2222.3 | D7: =DATA!C8-D9 -> -2615.1 | E7: =DATA!D8-E9 -> -3201 | F7: =F21*F4 -> -3301.5777 | G7: =G21*G4 -> -3677.2972 | H7: =H21*H4 -> -4095.7737 | I7: =I21*I4 -> -4561.8727 | J7: =J21*J4 -> -5081.0138
B8: EBITDA | C8: =SUM(C6:C7) -> 2742.5 | D8: =SUM(D6:D7) -> 3242.1 | E8: =SUM(E6:E7) -> 3879.5 | F8: =SUM(F6:F7) -> 4054.3207 | G8: =SUM(G6:G7) -> 4515.7024 | H8: =SUM(H6:H7) -> 5029.5893 | I8: =SUM(I6:I7) -> 5601.9566 | J8: =SUM(J6:J7) -> 6239.4592
B9: D&A | C9: =-DATA!B26 -> -323.6 | D9: =-DATA!C26 -> -348.1 | E9: =-DATA!D26 -> -379.4 | F9: ='FIXED ASSETS '!F5 -> -387.45499 | G9: ='FIXED ASSETS '!G5 -> -408.56524 | H9: ='FIXED ASSETS '!H5 -> -421.67876 | I9: ='FIXED ASSETS '!I5 -> -433.83951 | J9: ='FIXED ASSETS '!J5 -> -445.11669
B10: EBIT | C10: =SUM(C8:C9) -> 2418.9 | D10: =SUM(D8:D9) -> 2894 | E10: =SUM(E8:E9) -> 3500.1 | F10: =SUM(F8:F9) -> 3666.8657 | G10: =SUM(G8:G9) -> 4107.1371 | H10: =SUM(H8:H9) -> 4607.9106 | I10: =SUM(I8:I9) -> 5168.1171 | J10: =SUM(J8:J9) -> 5794.3425
B11: Interest expenses | C11: =SUM(DATA!B10,DATA!B11) -> -246.8 | D11: =SUM(DATA!C10,DATA!C11) -> -326.7 | E11: =SUM(DATA!D10,DATA!D11) -> -258.3 | F11: ='FINANCIAL LIABILITIES'!D24 -> -238.515 | G11: ='FINANCIAL LIABILITIES'!E24 -> -233.51752 | H11: ='FINANCIAL LIABILITIES'!F24 -> -228.27018 | I11: ='FINANCIAL LIABILITIES'!G24 -> -222.76046 | J11: ='FINANCIAL LIABILITIES'!H24 -> -216.97526
B12: EBT | C12: =SUM(C10:C11) -> 2172.1 | D12: =SUM(D10:D11) -> 2567.3 | E12: =SUM(E10:E11) -> 3241.8 | F12: =SUM(F10:F11) -> 3428.3507 | G12: =SUM(G10:G11) -> 3873.6196 | H12: =SUM(H10:H11) -> 4379.6404 | I12: =SUM(I10:I11) -> 4945.3566 | J12: =SUM(J10:J11) -> 5577.3673
B13: Taxes | C13: =-C23*C12 -> -412.699 | D13: =-D23*D12 -> -487.787 | E13: =-E23*E12 -> -615.942 | F13: =-F23*F12 -> -651.38663 | G13: =-G23*G12 -> -735.98773 | H13: =-H23*H12 -> -832.13167 | I13: =-I23*I12 -> -939.61776 | J13: =-J23*J12 -> -1059.6998
B14: Net Income | C14: =SUM(C12:C13) -> 1759.401 | D14: =SUM(D12:D13) -> 2079.513 | E14: =SUM(E12:E13) -> 2625.858 | F14: =SUM(F12:F13) -> 2776.9641 | G14: =SUM(G12:G13) -> 3137.6319 | H14: =SUM(H12:H13) -> 3547.5087 | I14: =SUM(I12:I13) -> 4005.7389 | J14: =SUM(J12:J13) -> 4517.6675
B16: Revenue growth %
B17: Selected Case | D17: =((D4/C4)-1)*100% -> 0.10542344 | E17: =((E4/D4)-1)*100% -> 0.12222247 | F17: =AVERAGE(D17:E17) -> 0.11382296 | G17: =11.38% -> 0.1138 | H17: =11.38% -> 0.1138 | I17: =11.38% -> 0.1138 | J17: =11.38% -> 0.1138
B18: Cogs as a % of Revenues
B19: Selected Case | C19: =C5/C4 -> -0.68953895 | D19: =D5/D4 -> -0.66866543 | E19: =E5/E4 -> -0.64308758 | F19: =AVERAGE(C19:E19) -> -0.66709732 | G19: =F19 -> -0.66709732 | H19: =G19 -> -0.66709732 | I19: =H19 -> -0.66709732 | J19: =I19 -> -0.66709732
B20: Operating Expense as a % of Revenues
B21: Selected Case | C21: =C7/C4 -> -0.13896584 | D21: =D7/D4 -> -0.14793298 | E21: =E7/E4 -> -0.16135536 | F21: =AVERAGE(C21:E21) -> -0.14941806 | G21: =F21 -> -0.14941806 | H21: =G21 -> -0.14941806 | I21: =H21 -> -0.14941806 | J21: =I21 -> -0.14941806
B23: Taxes | C23: 0.19 | D23: 0.19 | E23: 0.19 | F23: 0.19 | G23: 0.19 | H23: 0.19 | I23: 0.19 | J23: 0.19

Sheet FIXED ASSETS 
B2: Fixed Assets Rollforward | F2: Forecast
B3: $ in millions | C3: 44926 | D3: 45291 | E3: 45657 | F3: 42369 | G3: 46387 | H3: 46752 | I3: 47118 | J3: 47483
B4: Beginning Intangible Assets, PP&E | D4: =C7 -> 4800.1 | E4: =D7 -> 5212 | F4: =E7 -> 5332.7 | G4: =F7 -> 5623.249 | H4: =G7 -> 5803.7357 | I4: =H7 -> 5971.1089 | J4: =I7 -> 6126.3214
B5: D&A | D5: =-DATA!C26 -> -348.1 | E5: =-DATA!D26 -> -379.4 | F5: =F9*F4 -> -387.45499 | G5: =G9*G4 -> -408.56524 | H5: =H9*H4 -> -421.67876 | I5: =I9*I4 -> -433.83951 | J5: =J9*J4 -> -445.11669
B6: Capex & additions | D6: =D7-D4-D5 -> 760 | E6: =E7-E4-E5 -> 500.1 | F6: =F10*F4 -> 678.00397 | G6: =AVERAGE($E$6:$F$6) -> 589.05199 | H6: =AVERAGE($E$6:$F$6) -> 589.05199 | I6: =AVERAGE($E$6:$F$6) -> 589.05199 | J6: =AVERAGE($E$6:$F$6) -> 589.05199
B7: Ending Intangible Assets, PP&E | C7: =DATA!B74+DATA!B76 -> 4800.1 | D7: =DATA!C74+DATA!C76 -> 5212 | E7: =DATA!D74+DATA!D76 -> 5332.7 | F7: =SUM(F4:F6) -> 5623.249 | G7: =SUM(G4:G6) -> 5803.7357 | H7: =SUM(H4:H6) -> 5971.1089 | I7: =SUM(I4:I6) -> 6126.3214 | J7: =SUM(J4:J6) -> 6270.2567
B9: D&A as a % of Beginning PP&E | D9: =D5/D4 -> -0.072519323 | E9: =E5/E4 -> -0.072793553 | F9: =AVERAGE(D9:E9) -> -0.072656438 | G9: =F9 -> -0.072656438 | H9: =G9 -> -0.072656438 | I9: =H9 -> -0.072656438 | J9: =I9 -> -0.072656438
B10: Capex & additions as % of Beginning PP&E | D10: =D6/D4 -> 0.15833003 | E10: =E6/E4 -> 0.09595165 | F10: =AVERAGE(D10:E10) -> 0.12714084 | G10: =F10 -> 0.12714084 | H10: =G10 -> 0.12714084 | I10: =H10 -> 0.12714084 | J10: =I10 -> 0.12714084

Sheet BALANCE SHEET
B2: BALANCE SHEET | F2: Forecast
B3: $ in mln | C3: 44926 | D3: 45291 | E3: 45657 | F3: 46022 | G3: 46387 | H3: 46752 | I3: 47118 | J3: 47483
B4: Trade Receivables | C4: =DATA!B70 -> 2780.1 | D4: =DATA!C70 -> 2956.8 | E4: =DATA!D70 -> 3090.2 | F4: ='P&L'!F4*F18/360 -> 3659.7207 | G4: ='P&L'!G4*G18/360 -> 4076.1969 | H4: ='P&L'!H4*H18/360 -> 4540.0681 | I4: ='P&L'!I4*I18/360 -> 5056.7278 | J4: ='P&L'!J4*J18/360 -> 5632.1834
B5: Inventory | C5: =DATA!B71 -> 1993.8 | D5: =DATA!C71 -> 2152.1 | E5: =DATA!D71 -> 1971.5 | F5: =-F19*'P&L'!F5/360 -> 2542.2824 | G5: =-G19*'P&L'!G5/360 -> 2831.5941 | H5: =-H19*'P&L'!H5/360 -> 3153.8295 | I5: =-I19*'P&L'!I5/360 -> 3512.7353 | J5: =-J19*'P&L'!J5/360 -> 3912.4846
B6: Intangible Assets, PP&E | C6: ='FIXED ASSETS '!C7 -> 4800.1 | D6: ='FIXED ASSETS '!D7 -> 5212 | E6: ='FIXED ASSETS '!E7 -> 5332.7 | F6: ='FIXED ASSETS '!F7 -> 5623.249 | G6: ='FIXED ASSETS '!G7 -> 5803.7357 | H6: ='FIXED ASSETS '!H7 -> 5971.1089 | I6: ='FIXED ASSETS '!I7 -> 6126.3214 | J6: ='FIXED ASSETS '!J7 -> 6270.2567
B7: Goodwill | C7: =DATA!B75 -> 5503.7 | D7: =DATA!C75 -> 6095.3 | E7: =DATA!D75 -> 6127.9 | F7: =E7 -> 6127.9 | G7: =F7 -> 6127.9 | H7: =G7 -> 6127.9 | I7: =H7 -> 6127.9 | J7: =I7 -> 6127.9
B8: Cash | C8: =DATA!B69 -> 1220.5 | D8: =DATA!C69 -> 1095.3 | E8: =DATA!D69 -> 1590.1 | F8: =E8+'CASH FLOW'!C19 -> 2866.6902 | G8: =F8+'CASH FLOW'!D19 -> 4771.4155 | H8: =G8+'CASH FLOW'!E19 -> 6952.619 | I8: =H8+'CASH FLOW'!F19 -> 9439.7599 | J8: =I8+'CASH FLOW'!G19 -> 12265.659
B9: Other assets | C9: =SUM(DATA!B77,DATA!B72) -> 1783.4 | D9: =SUM(DATA!C77,DATA!C72) -> 1880.4 | E9: =SUM(DATA!D77,DATA!D72) -> 2034.3 | F9: =F21*'P&L'!F4 -> 2360.1501 | G9: =G21*'P&L'!G4 -> 2628.7351 | H9: =H21*'P&L'!H4 -> 2927.8852 | I9: =I21*'P&L'!I4 -> 3261.0785 | J9: =J21*'P&L'!J4 -> 3632.1893
B10: Assets | C10: =SUM(C4:C9) -> 18081.6 | D10: =SUM(D4:D9) -> 19391.9 | E10: =SUM(E4:E9) -> 20146.7 | F10: =SUM(F4:F9) -> 23179.992 | G10: =SUM(G4:G9) -> 26239.577 | H10: =SUM(H4:H9) -> 29673.411 | I10: =SUM(I4:I9) -> 33524.523 | J10: =SUM(J4:J9) -> 37840.673
B11: Trade Payables | C11: =DATA!B79 -> 2091.6 | D11: =DATA!C79 -> 2025.2 | E11: =DATA!D79 -> 2148 | F11: =-F20*'P&L'!F5/360 -> 2601.0881 | G11: =-G20*'P&L'!G5/360 -> 2897.092 | H11: =-H20*'P&L'!H5/360 -> 3226.781 | I11: =-I20*'P&L'!I5/360 -> 3593.9887 | J11: =-J20*'P&L'!J5/360 -> 4002.9846 | N11: =DATA!F80-M11 -> 0
B12: Provisions | C12: =SUM(DATA!B80,DATA!B81,DATA!B85,DATA!B86) -> 3894.3 | D12: =SUM(DATA!C80,DATA!C81,DATA!C85,DATA!C86) -> 4527 | E12: =SUM(DATA!D80,DATA!D81,DATA!D85,DATA!D86) -> 4617.2 | F12: =E12 -> 4617.2 | G12: =F12 -> 4617.2 | H12: =G12 -> 4617.2 | I12: =H12 -> 4617.2 | J12: =I12 -> 4617.2
B13: Financial Liabilities | C13: =SUM(DATA!B82,DATA!B84) -> 4836.3 | D13: =SUM(DATA!C82,DATA!C84) -> 4779.8 | E13: =SUM(DATA!D82,DATA!D84) -> 4770.3 | F13: ='FINANCIAL LIABILITIES'!G13 -> 5147.3805 | G13: ='FINANCIAL LIABILITIES'!H13 -> 5557.1716 | H13: ='FINANCIAL LIABILITIES'!I13 -> 6002.6944 | I13: ='FINANCIAL LIABILITIES'!J13 -> 6487.2598 | J13: ='FINANCIAL LIABILITIES'!K13 -> 7014.4965
B14: Other Liabilities | C14: =SUM(DATA!B87) -> 1154.2 | D14: =SUM(DATA!C87) -> 1042.9 | E14: =SUM(DATA!D87) -> 1124.3 | F14: =F22*'P&L'!F4 -> 1383.5488 | G14: =G22*'P&L'!G4 -> 1540.9967 | H14: =H22*'P&L'!H4 -> 1716.3621 | I14: =I22*'P&L'!I4 -> 1911.6841 | J14: =J22*'P&L'!J4 -> 2129.2338
B15: Equity | C15: =DATA!B95 -> 6105.2 | D15: =DATA!C95 -> 7017 | E15: =DATA!D95 -> 7486.9 | F15: =EQUITY!F12 -> 9430.7748 | G15: =EQUITY!G12 -> 11627.117 | H15: =EQUITY!H12 -> 14110.373 | I15: =EQUITY!I12 -> 16914.39 | J15: =EQUITY!J12 -> 20076.758
B16: Liabilities & Equity | C16: =SUM(C11:C15) -> 18081.6 | D16: =SUM(D11:D15) -> 19391.9 | E16: =SUM(E11:E15) -> 20146.7 | F16: =SUM(F11:F15) -> 23179.992 | G16: =SUM(G11:G15) -> 26239.577 | H16: =SUM(H11:H15) -> 29673.411 | I16: =SUM(I11:I15) -> 33524.523 | J16: =SUM(J11:J15) -> 37840.673
B18: DSO | C18: =C4/'P&L'!C4*360 -> 62.584716 | D18: =D4/'P&L'!D4*360 -> 60.214509 | E18: =E4/'P&L'!E4*360 -> 56.077265 | F18: =AVERAGE($C18:$E18) -> 59.625497 | G18: =AVERAGE($C18:$E18) -> 59.625497 | H18: =AVERAGE($C18:$E18) -> 59.625497 | I18: =AVERAGE($C18:$E18) -> 59.625497 | J18: =AVERAGE($C18:$E18) -> 59.625497
B19: DIO | C19: =-C5/'P&L'!C5*360 -> 65.092456 | D19: =-D5/'P&L'!D5*360 -> 65.543975 | E19: =-E5/'P&L'!E5*360 -> 55.632285 | F19: =AVERAGE($C19:$E19) -> 62.089572 | G19: =AVERAGE($C19:$E19) -> 62.089572 | H19: =AVERAGE($C19:$E19) -> 62.089572 | I19: =AVERAGE($C19:$E19) -> 62.089572 | J19: =AVERAGE($C19:$E19) -> 62.089572
B20: DPO | C20: =-C11/'P&L'!C5*360 -> 68.285375 | D20: =-D11/'P&L'!D5*360 -> 61.679131 | E20: =-E11/'P&L'!E5*360 -> 60.612806 | F20: =AVERAGE($C20:$E20) -> 63.525771 | G20: =AVERAGE($C20:$E20) -> 63.525771 | H20: =AVERAGE($C20:$E20) -> 63.525771 | I20: =AVERAGE($C20:$E20) -> 63.525771 | J20: =AVERAGE($C20:$E20) -> 63.525771
B21: Other Assets % | C21: =C9/'P&L'!C4 -> 0.11152035 | D21: =D9/'P&L'!D4 -> 0.10637191 | E21: =E9/'P&L'!E4 -> 0.10254459 | F21: =AVERAGE($C21:$E21) -> 0.10681228 | G21: =AVERAGE($C21:$E21) -> 0.10681228 | H21: =AVERAGE($C21:$E21) -> 0.10681228 | I21: =AVERAGE($C21:$E21) -> 0.10681228 | J21: =AVERAGE($C21:$E21) -> 0.10681228
B22: Other Liabilities % | C22: =C14/'P&L'!C4 -> 0.072174941 | D22: =D14/'P&L'!D4 -> 0.058995565 | E22: =E14/'P&L'!E4 -> 0.056673489 | F22: =AVERAGE($C22:$E22) -> 0.062614665 | G22: =AVERAGE($C22:$E22) -> 0.062614665 | H22: =AVERAGE($C22:$E22) -> 0.062614665 | I22: =AVERAGE($C22:$E22) -> 0.062614665 | J22: =AVERAGE($C22:$E22) -> 0.062614665
B24: Check | C24: =C10-C16 -> 0 | D24: =D10-D16 -> 0 | E24: =E10-E16 -> 0 | F24: =F10-F16 -> 0 | G24: =G10-G16 -> 0 | H24: =H10-H16 -> 0 | I24: =I10-I16 -> 0 | J24: =J10-J16 -> 0

Sheet FINANCIAL LIABILITIES
C7: Financial Liabilities | G7: Forecast
C8: $ in millions | D8: 2022 | E8: =D8+1 -> 2023 | F8: =E8+1 -> 2024 | G8: =F8+1 -> 2025 | H8: =G8+1 -> 2026 | I8: =H8+1 -> 2027 | J8: =I8+1 -> 2028 | K8: =J8+1 -> 2029
C9: Beginning Debt | E9: =D13 -> 4836.3 | F9: =E13 -> 4779.8 | G9: =F13 -> 4770.3 | H9: =G13 -> 5147.3805 | I9: =H13 -> 5557.1716 | J9: =I13 -> 6002.6944 | K9: =J13 -> 6487.2598
C10: Short term Debt | E10: =DATA!C82 -> 801.9 | F10: =DATA!D82 -> 452.2 | G10: =F13*G15 -> 477.03 | H10: =G13*H15 -> 514.73805 | I10: =H13*I15 -> 555.71716 | J10: =I13*J15 -> 600.26944 | K10: =J13*K15 -> 648.72598
C11: New debt | E11: =DATA!C48 -> 699.2 | F11: =DATA!D48 -> 498.5 | G11: 0 | H11: 0 | I11: 0 | J11: 0 | K11: 0
C12: Principal repayment | E12: =E13-E9-E11 -> -755.7 | F12: =F13-F9-F11 -> -508 | G12: =D25 -> -99.949507 | H12: =E25 -> -104.94698 | I12: =F25 -> -110.19433 | J12: =G25 -> -115.70405 | K12: =H25 -> -121.48925
C13: Ending Debt | D13: =SUM(DATA!B84,DATA!B82) -> 4836.3 | E13: =SUM(DATA!C84,DATA!C82) -> 4779.8 | F13: =SUM(DATA!D84,DATA!D82) -> 4770.3 | G13: =SUM(G9:G12) -> 5147.3805 | H13: =SUM(H9:H12) -> 5557.1716 | I13: =SUM(I9:I12) -> 6002.6944 | J13: =SUM(J9:J12) -> 6487.2598 | K13: =SUM(K9:K12) -> 7014.4965
C15: Short term Debt as 10% of long term debt | G15: 0.1 | H15: 0.1 | I15: 0.1 | J15: 0.1 | K15: 0.1
C17: Interest rate after 2024 | D17: 0.05
C18: Repay debt in 10 years | D18: 25
C19: Annual payment: | D19: =PMT(D17,D18,F13) -> -338.46451
C21: Interest Rate | D21: =D17 -> 0.05 | E21: =D21 -> 0.05 | F21: =E21 -> 0.05 | G21: =F21 -> 0.05 | H21: =G21 -> 0.05 | I21: =H21 -> 0.05 | J21: =I21 -> 0.05 | K21: =J21 -> 0.05 | L21: =K21 -> 0.05 | ... AB21: =AA21 -> 0.05
C22: Period | D22: 1 | E22: 2 | F22: 3 | G22: 4 | H22: 5 | I22: 6 | J22: 7 | K22: 8 | L22: 9 | M22: 10 | N22: =M22+1 -> 11 | O22: =N22+1 -> 12 | P22: =O22+1 -> 13 | Q22: =P22+1 -> 14 | R22: =Q22+1 -> 15 | S22: =R22+1 -> 16 | T22: =S22+1 -> 17 | U22: =T22+1 -> 18 | ... AB22: =AA22+1 -> 25
C23: Payment | D23: =D19 -> -338.46451 | E23: =D23 -> -338.46451 | F23: =E23 -> -338.46451 | G23: =F23 -> -338.46451 | H23: =G23 -> -338.46451 | I23: =H23 -> -338.46451 | J23: =I23 -> -338.46451 | K23: =J23 -> -338.46451 | L23: =K23 -> -338.46451 | ... AB23: =AA23 -> -338.46451
C24: Interest | D24: =-D21*F13 -> -238.515 | E24: =-E21*D26 -> -233.51752 | F24: =-F21*E26 -> -228.27018 | G24: =-G21*F26 -> -222.76046 | H24: =-H21*G26 -> -216.97526 | I24: =-I21*H26 -> -210.90079 | J24: =-J21*I26 -> -204.52261 | K24: =-K21*J26 -> -197.82551 | L24: =-L21*K26 -> -190.79356 | ... AB24: =-AB21*AA26 -> -16.117357
C25: Principal repayment | D25: =D23-D24 -> -99.949507 | E25: =E23-E24 -> -104.94698 | F25: =F23-F24 -> -110.19433 | G25: =G23-G24 -> -115.70405 | H25: =H23-H24 -> -121.48925 | I25: =I23-I24 -> -127.56371 | J25: =J23-J24 -> -133.9419 | K25: =K23-K24 -> -140.63899 | ... AB25: =AB23-AB24 -> -322.34715
C26: Residual debt | D26: =D25+F13 -> 4670.3505 | E26: =D26+E25 -> 4565.4035 | F26: =E26+F25 -> 4455.2092 | G26: =F26+G25 -> 4339.5051 | H26: =G26+H25 -> 4218.0159 | I26: =H26+I25 -> 4090.4522 | J26: =I26+J25 -> 3956.5103 | K26: =J26+K25 -> 3815.8713 | L26: =K26+L25 -> 3668.2003 | ... AB26: =AA26+AB25 -> -2.0463631e-12

Sheet EQUITY
B4: Equity Schedule | F4: Forecast
B5: $ in mln | C5: 44926 | D5: 45291 | E5: 45657 | F5: 46022 | G5: 46387 | H5: 46752 | I5: 47118 | J5: 47483
B6: Beginning Equity | D6: =C12 -> 6105.2 | E6: =D12 -> 7017 | F6: =E12 -> 7486.9 | G6: =F12 -> 9430.7748 | H6: =G12 -> 11627.117 | I6: =H12 -> 14110.373 | J6: =I12 -> 16914.39
B7: Shares Issued | D7: =DATA!C54 -> 79.3 | E7: =DATA!D54 -> 46.9 | F7: =0 -> 0 | G7: =0 -> 0 | H7: 0 | I7: 0 | J7: 0
B8: Accumulated other Comperihensive income | D8: =-(DATA!B92-DATA!C92) -> 95.4 | E8: =DATA!C92-DATA!D92 -> 193.3 | F8: 0 | G8: 0 | H8: 0 | I8: 0 | J8: 0
B9: Net Income | D9: ='P&L'!D14 -> 2079.513 | E9: ='P&L'!E14 -> 2625.858 | F9: ='P&L'!F14 -> 2776.9641 | G9: ='P&L'!G14 -> 3137.6319 | H9: ='P&L'!H14 -> 3547.5087 | I9: ='P&L'!I14 -> 4005.7389 | J9: ='P&L'!J14 -> 4517.6675
B10: Shares Buybacks | D10: =DATA!C55 -> -669.3 | E10: =DATA!D55 -> -1280.8 | F10: 0 | G10: =F10 -> 0 | H10: =AVERAGE(F10:G10) -> 0 | I10: =AVERAGE(G10:H10) -> 0 | J10: =AVERAGE(H10:I10) -> 0
B11: Dividends | D11: =DATA!C52 -> -683.7 | E11: =DATA!D52 -> -757.5 | F11: =-F9*F14 -> -833.08922 | G11: =-G9*G14 -> -941.28957 | H11: =-H9*H14 -> -1064.2526 | I11: =-I9*I14 -> -1201.7217 | J11: =-J9*J14 -> -1355.3003
B12: Ending Equity | C12: =DATA!B95 -> 6105.2 | D12: =DATA!C95 -> 7017 | E12: ='BALANCE SHEET'!E15 -> 7486.9 | F12: =SUM(F6:F11) -> 9430.7748 | G12: =SUM(G6:G11) -> 11627.117 | H12: =SUM(H6:H11) -> 14110.373 | I12: =SUM(I6:I11) -> 16914.39 | J12: =SUM(J6:J11) -> 20076.758
B14: Dividends as a % of Net Income | F14: 0.3 | G14: =F14 -> 0.3 | H14: =G14 -> 0.3 | I14: =H14 -> 0.3 | J14: =I14 -> 0.3
H18: =F12-E12 -> 1943.8748

Sheet CASH FLOW
B2: Cash Flow | C2: Forecast
B3: $ in millions | C3: 2025 | D3: 2026 | E3: =D3+1 -> 2027 | F3: =E3+1 -> 2028 | G3: =F3+1 -> 2029
B4: EBITDA | C4: ='P&L'!F8 -> 4054.3207 | D4: ='P&L'!G8 -> 4515.7024 | E4: ='P&L'!H8 -> 5029.5893 | F4: ='P&L'!I8 -> 5601.9566 | G4: ='P&L'!J8 -> 6239.4592
B5: Interest expenses | C5: ='P&L'!F11 -> -238.515 | D5: ='P&L'!G11 -> -233.51752 | E5: ='P&L'!H11 -> -228.27018 | F5: ='P&L'!I11 -> -222.76046 | G5: ='P&L'!J11 -> -216.97526
B6: Taxes | C6: ='P&L'!F13 -> -651.38663 | D6: ='P&L'!G13 -> -735.98773 | E6: ='P&L'!H13 -> -832.13167 | F6: ='P&L'!I13 -> -939.61776 | G6: ='P&L'!J13 -> -1059.6998
B7: Change in Trade Receivables | C7: =-('BALANCE SHEET'!F4-'BALANCE SHEET'!E4) -> -569.52065 | D7: =-('BALANCE SHEET'!G4-'BALANCE SHEET'!F4) -> -416.47621 | E7: =-('BALANCE SHEET'!H4-'BALANCE SHEET'!G4) -> -463.8712 | F7: =-('BALANCE SHEET'!I4-'BALANCE SHEET'!H4) -> -516.65975 | G7: =-('BALANCE SHEET'!J4-'BALANCE SHEET'!I4) -> -575.45562
B8: Change in Inventory | C8: =-('BALANCE SHEET'!F5-'BALANCE SHEET'!E5) -> -570.78238 | D8: =-('BALANCE SHEET'!G5-'BALANCE SHEET'!F5) -> -289.31174 | E8: =-('BALANCE SHEET'!H5-'BALANCE SHEET'!G5) -> -322.23541 | F8: =-('BALANCE SHEET'!I5-'BALANCE SHEET'!H5) -> -358.9058 | G8: =-('BALANCE SHEET'!J5-'BALANCE SHEET'!I5) -> -399.74928
B9: Change in Trade Payables | C9: ='BALANCE SHEET'!F11-'BALANCE SHEET'!E11 -> 453.08812 | D9: ='BALANCE SHEET'!G11-'BALANCE SHEET'!F11 -> 296.00383 | E9: ='BALANCE SHEET'!H11-'BALANCE SHEET'!G11 -> 329.68906 | F9: ='BALANCE SHEET'!I11-'BALANCE SHEET'!H11 -> 367.20768 | G9: ='BALANCE SHEET'!J11-'BALANCE SHEET'!I11 -> 408.99591
B10: Change in Other assets | C10: =-('BALANCE SHEET'!F9-'BALANCE SHEET'!E9) -> -325.85007 | D10: =-('BALANCE SHEET'!G9-'BALANCE SHEET'!F9) -> -268.58508 | E10: =-('BALANCE SHEET'!H9-'BALANCE SHEET'!G9) -> -299.15006 | F10: =-('BALANCE SHEET'!I9-'BALANCE SHEET'!H9) -> -333.19334 | G10: =-('BALANCE SHEET'!J9-'BALANCE SHEET'!I9) -> -371.11074
B11: Change in Other liabilities | C11: ='BALANCE SHEET'!F14-'BALANCE SHEET'!E14 -> 259.24882 | D11: ='BALANCE SHEET'!G14-'BALANCE SHEET'!F14 -> 157.44786 | E11: ='BALANCE SHEET'!H14-'BALANCE SHEET'!G14 -> 175.36542 | F11: ='BALANCE SHEET'!I14-'BALANCE SHEET'!H14 -> 195.32201 | G11: ='BALANCE SHEET'!J14-'BALANCE SHEET'!I14 -> 217.54965
B12: Capex & Addtions | C12: =-'FIXED ASSETS '!F6 -> -678.00397 | D12: =-'FIXED ASSETS '!G6 -> -589.05199 | E12: =-'FIXED ASSETS '!H6 -> -589.05199 | F12: =-'FIXED ASSETS '!I6 -> -589.05199 | G12: =-'FIXED ASSETS '!J6 -> -589.05199
B13: Operating Cash Flow | C13: =SUM(C4:C12) -> 1732.5989 | D13: =SUM(D4:D12) -> 2436.2238 | E13: =SUM(E4:E12) -> 2799.9333 | F13: =SUM(F4:F12) -> 3204.2972 | G13: =SUM(G4:G12) -> 3653.9621
B14: Dividends | C14: =EQUITY!F11 -> -833.08922 | D14: =EQUITY!G11 -> -941.28957 | E14: =EQUITY!H11 -> -1064.2526 | F14: =EQUITY!I11 -> -1201.7217 | G14: =EQUITY!J11 -> -1355.3003
B15: Change in Financial Liabilities | C15: ='FINANCIAL LIABILITIES'!G13-'FINANCIAL LIABILITIES'!F13 -> 377.08049 | D15: ='FINANCIAL LIABILITIES'!H13-'FINANCIAL LIABILITIES'!G13 -> 409.79107 | E15: ='FINANCIAL LIABILITIES'!I13-'FINANCIAL LIABILITIES'!H13 -> 445.52282 | F15: ='FINANCIAL LIABILITIES'!J13-'FINANCIAL LIABILITIES'!I13 -> 484.56539 | G15: ='FINANCIAL LIABILITIES'!K13-'FINANCIAL LIABILITIES'!J13 -> 527.23673
B16: Change in Goodwills | C16: 0 | D16: 0 | E16: 0 | F16: 0 | G16: 0
B17: Change in Provisions | C17: ='[1]Balance Sheet'!E13-'[1]Balance Sheet'!D13 -> 0 | D17: ='[1]Balance Sheet'!F13-'[1]Balance Sheet'!E13 -> 0 | E17: ='[1]Balance Sheet'!G13-'[1]Balance Sheet'!F13 -> 0 | F17: ='[1]Balance Sheet'!H13-'[1]Balance Sheet'!G13 -> 0 | G17: ='[1]Balance Sheet'!I13-'[1]Balance Sheet'!H13 -> 0
B18: Change in Equity | C18: =0 -> 0 | D18: =0 -> 0 | E18: =0 -> 0 | F18: =0 -> 0 | G18: =0 -> 0
B19: Net Cash Flow | C19: =SUM(C13:C18) -> 1276.5902 | D19: =SUM(D13:D18) -> 1904.7253 | E19: =SUM(E13:E18) -> 2181.2035 | F19: =SUM(F13:F18) -> 2487.1409 | G19: =SUM(G13:G18) -> 2825.8986

Sheet FIRM VALUE
C4: DEBT-EQUITY | D4: 44926 | E4: 45291 | F4: 45657 | G4: 46022 | H4: 46387 | I4: 46752 | J4: 47118 | K4: 47483
C5: Debt | D5: =SUM('BALANCE SHEET'!C11,'BALANCE SHEET'!C12,'BALANCE SHEET'!C13,'BALANCE SHEET'!C14) -> 11976.4 | E5: =SUM('BALANCE SHEET'!D11,'BALANCE SHEET'!D12,'BALANCE SHEET'!D13,'BALANCE SHEET'!D14) -> 12374.9 | F5: =SUM('BALANCE SHEET'!E11,'BALANCE SHEET'!E12,'BALANCE SHEET'!E13,'BALANCE SHEET'!E14) -> 12659.8 | G5: =SUM('BALANCE SHEET'!F11,'BALANCE SHEET'!F12,'BALANCE SHEET'!F13,'BALANCE SHEET'!F14) -> 13749.217 | H5: =SUM('BALANCE SHEET'!G11,'BALANCE SHEET'!G12,'BALANCE SHEET'!G13,'BALANCE SHEET'!G14) -> 14612.46 | I5: =SUM('BALANCE SHEET'!H11,'BALANCE SHEET'!H12,'BALANCE SHEET'!H13,'BALANCE SHEET'!H14) -> 15563.037 | J5: =SUM('BALANCE SHEET'!I11,'BALANCE SHEET'!I12,'BALANCE SHEET'!I13,'BALANCE SHEET'!I14) -> 16610.133 | K5: =SUM('BALANCE SHEET'!J11,'BALANCE SHEET'!J12,'BALANCE SHEET'!J13,'BALANCE SHEET'!J14) -> 17763.915
C6: Equity | D6: =EQUITY!C12 -> 6105.2 | E6: =EQUITY!D12 -> 7017 | F6: =EQUITY!E12 -> 7486.9 | G6: =EQUITY!F12 -> 9430.7748 | H6: =EQUITY!G12 -> 11627.117 | I6: =EQUITY!H12 -> 14110.373 | J6: =EQUITY!I12 -> 16914.39 | K6: =EQUITY!J12 -> 20076.758
C8: Weight of Debt | D8: =D5/D10 -> 0.66235289 | E8: =E5/E10 -> 0.63814789 | F8: =F5/F10 -> 0.62838083 | G8: =G5/G10 -> 0.59315022 | H8: =H5/H10 -> 0.55688626 | I8: =I5/I10 -> 0.52447754 | J8: =J5/J10 -> 0.49546216 | K8: =K5/K10 -> 0.46943972
C9: Weight of Equity | D9: =D6/D10 -> 0.33764711 | E9: =E6/E10 -> 0.36185211 | F9: =F6/F10 -> 0.37161917 | G9: =G6/G10 -> 0.40684978 | H9: =H6/H10 -> 0.44311374 | I9: =I6/I10 -> 0.47552246 | J9: =J6/J10 -> 0.50453784 | K9: =K6/K10 -> 0.53056028
C10: Total Debt and Equity | D10: =D5+D6 -> 18081.6 | E10: =E5+E6 -> 19391.9 | F10: =F5+F6 -> 20146.7 | G10: =G5+G6 -> 23179.992 | H10: =H5+H6 -> 26239.577 | I10: =I5+I6 -> 29673.411 | J10: =J5+J6 -> 33524.523 | K10: =K5+K6 -> 37840.673
C11: WACC | D11: =D14*D8*(1-'P&L'!C23)+D9*D15 -> 0.14275643 | E11: =D14*E8*(1-'P&L'!D23)+E9*D15 -> 0.15008691 | F11: =D14*F8*(1-'P&L'!E23)+F9*D15 -> 0.15304487 | G11: =D14*G8*(1-'P&L'!F23)+G9*D15 -> 0.16371446 | H11: =D14*H8*(1-'P&L'!G23)+H9*D15 -> 0.174697 | I11: =D14*I8*(1-'P&L'!H23)+I9*D15 -> 0.18451198 | J11: =D14*J8*(1-'P&L'!I23)+J9*D15 -> 0.19329929 | K11: =D14*K8*(1-'P&L'!J23)+K9*D15 -> 0.20118018
C14: Cost of Debt | D14: ='FINANCIAL LIABILITIES'!D17 -> 0.05
C15: Cost of Equity / CAPM | D15: =D17+(D18*(D16-D17)) -> 0.34335
C16: Market Return | D16: 0.3
C17: Risk Free Rate | D17: 0.045
C18: Beta | D18: 1.17
D21: 2025 | E21: =D21+1 -> 2026 | F21: =E21+1 -> 2027 | G21: =F21+1 -> 2028 | H21: =G21+1 -> 2029
C22: Cash Flows | D22: ='CASH FLOW'!C19 -> 1276.5902 | E22: ='CASH FLOW'!D19 -> 1904.7253 | F22: ='CASH FLOW'!E19 -> 2181.2035 | G22: ='CASH FLOW'!F19 -> 2487.1409 | H22: ='CASH FLOW'!G19 -> 2825.8986
H23: =H22*(1+0.05) -> 2967.1935
C24: PV | D24: =PV(G11,1,0,-E24) -> 6354.6466 | E24: =PV(H11,1,0,-F24) -> 7394.9941 | F24: =PV(I11,1,0,-G24) -> 8686.8773 | G24: =PV(J11,1,0,-H24) -> 10289.71 | H24: =PV(K11,1,0,-I24) -> 12278.704 | I24: =H23/K11 -> 14748.936
D26: =PV(G11,1,0,-D22) -> 1096.9961 | E26: =PV(H11,2,0,-E22) -> 1380.3227 | F26: =PV(I11,3,0,-F22) -> 1312.435 | G26: =PV(J11,4,0,-G22) -> 1226.5997 | H26: =PV(K11,5,0,-H22) -> 1130.0972 | I26: =SUM(D26:H26) -> 6146.4508
